Workbook

Sheet MatchesDB
A1: Matches | B1: =SUM(COUNTIF(J11:J40,"W"),COUNTIF(J11:J40,"D"),COUNTIF(J11:J40,"L")) -> 9 | D1: 123
A2: Wins | B2: =COUNTIF(J11:J40,"W") -> 3
A3: Loses | B3: =COUNTIF(J11:J40,"L") -> 5
A4: Draws | B4: =COUNTIF(J11:J40,"D") -> 1
A5: Points | B5: =B2*3+B4 -> 10
A6: GD | B6: =B7-B8 -> 1
A7: Scored | B7: =SUM(K11:K40) -> 32
A8: Concede | B8: =SUM(L11:L40) -> 31
A10: # | B10: Q | C10: League | D10: Date | E10: Kickoff | F10: URL | G10: Opponent | H10: Address | I10: H/A | J10: W/D/L | K10: Scored | L10: Conceded | M10: Show up | N10: Adam | O10: Antek | P10: Ben | Q10: Ilay | R10: James | S10: Jesse | T10: Johan | U10: Ren | V10: Yahya | W10: Maddox | X10: Kay | Y10: Noam
A11: =IF(ISBLANK(B11),"",1) -> 1 | B11: 1 | C11: NVC Givaudan Kick-off Zomertornooi | D11: 46256 | E11: 0.55555556 | G11: HSV de Zuidvogels JO 11-3 | H11: NVC Givaudan Kick-off Zomertornooi | I11: A | J11: =IF(AND(NOT(ISBLANK(K11)),NOT(ISBLANK(L11))),IF(K11>L11,"W",IF(K11<L11,"L","D")),"") -> D | K11: {=IF(L11<>"", SUMPRODUCT(MID(N11:Y11,5,1)*1), "")} -> 0 | L11: 0 | M11: {=IF(L11<>"", SUMPRODUCT(LEFT(N11:Y11,1)*1), "")} -> 8 | N11: 0,0,0,0 | O11: 1,1,0,0 | P11: 1,1,0,0 | Q11: 1,1,0,0 | R11: 1,1,0,0 | S11: 1,1,0,0 | T11: 0,0,0,0 | U11: 1,1,0,0 | V11: 1,1,0,0 | W11: 1,1,0,0 | X11: 0,0,0,0 | Y11: 0,0,0,0
A12: =IF(ISBLANK(B12),"",A11+1) -> 2 | B12: 1 | C12: NVC Givaudan Kick-off Zomertornooi | D12: 46256 | E12: 0.59722222 | G12: Victoria JO11-4 | H12: NVC Givaudan Kick-off Zomertornooi | I12: A | J12: =IF(AND(NOT(ISBLANK(K12)),NOT(ISBLANK(L12))),IF(K12>L12,"W",IF(K12<L12,"L","D")),"") -> W | K12: {=IF(L12<>"", SUMPRODUCT(MID(N12:Y12,5,1)*1), "")} -> 1 | L12: 0 | M12: {=IF(L12<>"", SUMPRODUCT(LEFT(N12:Y12,1)*1), "")} -> 8 | N12: 1,1,0,0 | O12: 1,1,0,0 | P12: 1,1,0,0 | Q12: 1,1,0,0 | R12: 1,1,0,0 | S12: 1,1,0,0 | T12: 0,0,0,0 | U12: 1,1,0,0 | V12: 1,1,1,0 | W12: 0,0,0,0 | X12: 0,0,0,0 | Y12: 0,0,0,0
A13: =IF(ISBLANK(B13),"",A12+1) -> 3 | B13: 1 | C13: NVC Givaudan Kick-off Zomertornooi | D13: 46256 | E13: 0.63888889 | G13: NVC JO11-2 | H13: NVC Givaudan Kick-off Zomertornooi | I13: A | J13: =IF(AND(NOT(ISBLANK(K13)),NOT(ISBLANK(L13))),IF(K13>L13,"W",IF(K13<L13,"L","D")),"") -> W | K13: {=IF(L13<>"", SUMPRODUCT(MID(N13:Y13,5,1)*1), "")} -> 8 | L13: 0 | M13: {=IF(L13<>"", SUMPRODUCT(LEFT(N13:Y13,1)*1), "")} -> 8 | N13: 1,1,0,0 | O13: 1,1,2,0 | P13: 1,1,2,0 | Q13: 1,1,2,0 | R13: 1,1,1,0 | S13: 1,1,0,0 | T13: 0,0,0,0 | U13: 1,1,1,0 | V13: 1,1,0,0 | W13: 0,0,0,0 | X13: 0,0,0,0 | Y13: 0,0,0,0
A14: =IF(ISBLANK(B14),"",A13+1) -> 4 | B14: 1 | C14: NVC Givaudan Kick-off Zomertornooi | D14: 46256 | E14: 0.68055556 | G14: SV Huizen JO11-2 | H14: NVC Givaudan Kick-off Zomertornooi | I14: A | J14: =IF(AND(NOT(ISBLANK(K14)),NOT(ISBLANK(L14))),IF(K14>L14,"W",IF(K14<L14,"L","D")),"") -> L | K14: {=IF(L14<>"", SUMPRODUCT(MID(N14:Y14,5,1)*1), "")} -> 0 | L14: 1 | M14: {=IF(L14<>"", SUMPRODUCT(LEFT(N14:Y14,1)*1), "")} -> 8 | N14: 1,1,0,0 | O14: 1,1,0,0 | P14: 1,1,0,0 | Q14: 1,1,0,0 | R14: 1,1,0,0 | S14: 1,1,0,0 | T14: 0,0,0,0 | U14: 1,1,0,0 | V14: 1,1,0,0 | W14: 0,0,0,0 | X14: 0,0,0,0 | Y14: 0,0,0,0
A15: =IF(ISBLANK(B15),"",A14+1) -> 5 | B15: 1 | C15: 1e 21 | D15: 46270 | E15: 0.42708333 | G15: CTO '70 JO11-1 | H15: Biesbosch 39, 1115 HE Duivendrecht | I15: A | J15: =IF(AND(NOT(ISBLANK(K15)),NOT(ISBLANK(L15))),IF(K15>L15,"W",IF(K15<L15,"L","D")),"") -> L | K15: {=IF(L15<>"", SUMPRODUCT(MID(N15:Y15,5,1)*1), "")} -> 2 | L15: 7 | M15: {=IF(L15<>"", SUMPRODUCT(LEFT(N15:Y15,1)*1), "")} -> 9 | N15: 1,1,0,0 | O15: 1,1,1,0 | P15: 1,1,0,1 | Q15: 1,1,1,0 | R15: 1,1,0,0 | S15: 1,1,0,0 | T15: 1,1,0,0 | U15: 1,1,0,1 | V15: 1,0,0,0 | W15: 0,0,0,0 | X15: 0,0,0,0 | Y15: 0,0,0,0
A16: =IF(ISBLANK(B16),"",A15+1) -> 6 | B16: 1 | C16: Oefen | D16: 46277 | E16: 0.375 | G16: FC Amsterdam JO11-2 | H16: Escapade 5, 1183 NM Amstelveen | I16: H | J16: =IF(AND(NOT(ISBLANK(K16)),NOT(ISBLANK(L16))),IF(K16>L16,"W",IF(K16<L16,"L","D")),"") -> W | K16: {=IF(L16<>"", SUMPRODUCT(MID(N16:Y16,5,1)*1), "")} -> 10 | L16: 3 | M16: {=IF(L16<>"", SUMPRODUCT(LEFT(N16:Y16,1)*1), "")} -> 9 | N16: 1,1,0,0 | O16: 1,1,4,1 | P16: 1,1,0,2 | Q16: 0,0,0,0 | R16: 0,0,0,0 | S16: 1,1,0,0 | T16: 1,1,1,0 | U16: 1,1,1,4 | V16: 1,1,1,1 | W16: 0,0,0,0 | X16: 1,1,1,1 | Y16: 1,1,2,0
A17: =IF(ISBLANK(B17),"",A16+1) -> 7 | B17: 1 | C17: 1e 21 | D17: 46284 | E17: 0.35416667 | G17: Buitenveldert JO11-3 | H17: Gustav Mahlerlaan 2009, 1081 LB Amsterdam | I17: A | J17: =IF(AND(NOT(ISBLANK(K17)),NOT(ISBLANK(L17))),IF(K17>L17,"W",IF(K17<L17,"L","D")),"") -> L | K17: {=IF(L17<>"", SUMPRODUCT(MID(N17:Y17,5,1)*1), "")} -> 6 | L17: 10 | M17: {=IF(L17<>"", SUMPRODUCT(LEFT(N17:Y17,1)*1), "")} -> 11 | N17: 1,1,0,0 | O17: 1,1,2,1 | P17: 1,1,1,1 | Q17: 1,0,0,1 | R17: 1,1,0,0 | S17: 1,0,0,1 | T17: 1,1,0,0 | U17: 1,1,3,0 | V17: 1,1,0,0 | W17: 0,0,0,0 | X17: 1,1,0,0 | Y17: 1,0,0,0
A18: =IF(ISBLANK(B18),"",A17+1) -> 8 | B18: 1 | C18: 1e 21 | D18: 46291 | E18: 0.375 | G18: Abcoude JO11-2 | H18: Escapade 5, 1183 NM Amstelveen | I18: H | J18: =IF(AND(NOT(ISBLANK(K18)),NOT(ISBLANK(L18))),IF(K18>L18,"W",IF(K18<L18,"L","D")),"") -> L | K18: {=IF(L18<>"", SUMPRODUCT(MID(N18:Y18,5,1)*1), "")} -> 3 | L18: 5 | M18: {=IF(L18<>"", SUMPRODUCT(LEFT(N18:Y18,1)*1), "")} -> 11 | N18: 1,1,0,0 | O18: 1,1,0,1 | P18: 1,1,1,0 | Q18: 1,1,0,1 | R18: 1,1,1,0 | S18: 1,1,0,0 | T18: 1,0,0,0 | U18: 1,1,1,0 | V18: 1,0,0,0 | W18: 0,0,0,0 | X18: 1,1,0,0 | Y18: 1,0,0,0
A19: =IF(ISBLANK(B19),"",A18+1) -> 9 | B19: 1 | C19: 1e 21 | D19: 46298 | E19: 0.375 | G19: Zuidoost United JO11-1 | H19: Escapade 5, 1183 NM Amstelveen | I19: H | J19: =IF(AND(NOT(ISBLANK(K19)),NOT(ISBLANK(L19))),IF(K19>L19,"W",IF(K19<L19,"L","D")),"") -> L | K19: {=IF(L19<>"", SUMPRODUCT(MID(N19:Y19,5,1)*1), "")} -> 2 | L19: 5 | M19: {=IF(L19<>"", SUMPRODUCT(LEFT(N19:Y19,1)*1), "")} -> 11 | N19: 1,1,0,0 | O19: 1,1,0,0 | P19: 1,1,0,1 | Q19: 1,1,0,0 | R19: 1,1,0,0 | S19: 1,1,0,0 | T19: 1,0,1,0 | U19: 1,1,1,0 | V19: 1,0,0,0 | W19: 0,0,0,0 | X19: 1,1,0,0 | Y19: 1,0,0,0
A20: =IF(ISBLANK(B20),"",A19+1) -> 10 | B20: 1 | C20: 2e 23 | D20: 46319 | E20: 0.35416667 | G20: FC Amsterdam JO11-2 | H20: Buitensingel 8, 1114 BE Duivendrecht | I20: A | J20: =IF(AND(NOT(ISBLANK(K20)),NOT(ISBLANK(L20))),IF(K20>L20,"W",IF(K20<L20,"L","D")),"") | K20: {=IF(L20<>"", SUMPRODUCT(MID(N20:Y20,5,1)*1), "")} | M20: {=IF(L20<>"", SUMPRODUCT(LEFT(N20:Y20,1)*1), "")}
A21: =IF(ISBLANK(B21),"",A20+1) -> 11 | B21: 1 | C21: 2e 23 | D21: 46326 | E21: 0.375 | G21: RODA'23 Rksv JO11-5 | H21: Escapade 5, 1183 NM Amstelveen | I21: H | J21: =IF(AND(NOT(ISBLANK(K21)),NOT(ISBLANK(L21))),IF(K21>L21,"W",IF(K21<L21,"L","D")),"") | K21: {=IF(L21<>"", SUMPRODUCT(MID(N21:Y21,5,1)*1), "")} | M21: {=IF(L21<>"", SUMPRODUCT(LEFT(N21:Y21,1)*1), "")}
A22: =IF(ISBLANK(B22),"",A21+1) -> 12 | B22: 1 | C22: 2e 23 | D22: 46333 | E22: 0.45833333 | G22: ASV Blauw-Wit JO11-3 | H22: Sloterweg 1043K, 1066 CC Amsterdam | I22: A | J22: =IF(AND(NOT(ISBLANK(K22)),NOT(ISBLANK(L22))),IF(K22>L22,"W",IF(K22<L22,"L","D")),"") | K22: {=IF(L22<>"", SUMPRODUCT(MID(N22:Y22,5,1)*1), "")} | M22: {=IF(L22<>"", SUMPRODUCT(LEFT(N22:Y22,1)*1), "")}
A23: =IF(ISBLANK(B23),"",A22+1) -> 13 | B23: 1 | C23: 2e 23 | D23: 46340 | E23: 0.44791667 | G23: ASV Arsenal JO11-2 | H23: Escapade 5, 1183 NM Amstelveen | I23: H | J23: =IF(AND(NOT(ISBLANK(K23)),NOT(ISBLANK(L23))),IF(K23>L23,"W",IF(K23<L23,"L","D")),"") | K23: {=IF(L23<>"", SUMPRODUCT(MID(N23:Y23,5,1)*1), "")} | M23: {=IF(L23<>"", SUMPRODUCT(LEFT(N23:Y23,1)*1), "")}
A24: =IF(ISBLANK(B24),"",A23+1) -> 14 | B24: 1 | C24: 2e 23 | D24: 46347 | E24: 0.35416667 | G24: Swift JO11-4 | H24: Olympiaplein 31, 1077 CL Amsterdam | I24: A | J24: =IF(AND(NOT(ISBLANK(K24)),NOT(ISBLANK(L24))),IF(K24>L24,"W",IF(K24<L24,"L","D")),"") | K24: {=IF(L24<>"", SUMPRODUCT(MID(N24:Y24,5,1)*1), "")} | M24: {=IF(L24<>"", SUMPRODUCT(LEFT(N24:Y24,1)*1), "")}
A25: =IF(ISBLANK(B25),"",A24+1) -> 15 | B25: 1 | C25: 2e 23 | D25: 46354 | E25: 0.44791667 | G25: Buitenveldert JO11-4 | H25: Escapade 5, 1183 NM Amstelveen | I25: H | J25: =IF(AND(NOT(ISBLANK(K25)),NOT(ISBLANK(L25))),IF(K25>L25,"W",IF(K25<L25,"L","D")),"") | K25: {=IF(L25<>"", SUMPRODUCT(MID(N25:Y25,5,1)*1), "")} | M25: {=IF(L25<>"", SUMPRODUCT(LEFT(N25:Y25,1)*1), "")}
A26: =IF(ISBLANK(B26),"",A25+1) -> 16 | B26: 1 | C26: 2e 23 | D26: 46361 | E26: 0.35416667 | G26: Sporting Martinus JO11-1 | H26: Amsterdamseweg 247, 1182 GZ Amstelveen | I26: A | J26: =IF(AND(NOT(ISBLANK(K26)),NOT(ISBLANK(L26))),IF(K26>L26,"W",IF(K26<L26,"L","D")),"") | K26: {=IF(L26<>"", SUMPRODUCT(MID(N26:Y26,5,1)*1), "")} | M26: {=IF(L26<>"", SUMPRODUCT(LEFT(N26:Y26,1)*1), "")}
A27: =IF(ISBLANK(B27),"",A26+1) | J27: =IF(AND(NOT(ISBLANK(K27)),NOT(ISBLANK(L27))),IF(K27>L27,"W",IF(K27<L27,"L","D")),"") | K27: {=IF(L27<>"", SUMPRODUCT(MID(N27:Y27,5,1)*1), "")} | M27: {=IF(L27<>"", SUMPRODUCT(LEFT(N27:Y27,1)*1), "")}
A28: =IF(ISBLANK(B28),"",A27+1) | J28: =IF(AND(NOT(ISBLANK(K28)),NOT(ISBLANK(L28))),IF(K28>L28,"W",IF(K28<L28,"L","D")),"") | K28: {=IF(L28<>"", SUMPRODUCT(MID(N28:Y28,5,1)*1), "")} | M28: {=IF(L28<>"", SUMPRODUCT(LEFT(N28:Y28,1)*1), "")}
A29: =IF(ISBLANK(B29),"",A28+1) | J29: =IF(AND(NOT(ISBLANK(K29)),NOT(ISBLANK(L29))),IF(K29>L29,"W",IF(K29<L29,"L","D")),"") | K29: {=IF(L29<>"", SUMPRODUCT(MID(N29:Y29,5,1)*1), "")} | M29: {=IF(L29<>"", SUMPRODUCT(LEFT(N29:Y29,1)*1), "")}
A30: =IF(ISBLANK(B30),"",A29+1) | J30: =IF(AND(NOT(ISBLANK(K30)),NOT(ISBLANK(L30))),IF(K30>L30,"W",IF(K30<L30,"L","D")),"") | K30: {=IF(L30<>"", SUMPRODUCT(MID(N30:Y30,5,1)*1), "")} | M30: {=IF(L30<>"", SUMPRODUCT(LEFT(N30:Y30,1)*1), "")}
A31: =IF(ISBLANK(B31),"",A30+1) | J31: =IF(AND(NOT(ISBLANK(K31)),NOT(ISBLANK(L31))),IF(K31>L31,"W",IF(K31<L31,"L","D")),"") | K31: {=IF(L31<>"", SUMPRODUCT(MID(N31:Y31,5,1)*1), "")} | M31: {=IF(L31<>"", SUMPRODUCT(LEFT(N31:Y31,1)*1), "")}
A32: =IF(ISBLANK(B32),"",A31+1) | J32: =IF(AND(NOT(ISBLANK(K32)),NOT(ISBLANK(L32))),IF(K32>L32,"W",IF(K32<L32,"L","D")),"") | K32: {=IF(L32<>"", SUMPRODUCT(MID(N32:Y32,5,1)*1), "")} | M32: {=IF(L32<>"", SUMPRODUCT(LEFT(N32:Y32,1)*1), "")}
A33: =IF(ISBLANK(B33),"",A32+1) | J33: =IF(AND(NOT(ISBLANK(K33)),NOT(ISBLANK(L33))),IF(K33>L33,"W",IF(K33<L33,"L","D")),"") | K33: {=IF(L33<>"", SUMPRODUCT(MID(N33:Y33,5,1)*1), "")} | M33: {=IF(L33<>"", SUMPRODUCT(LEFT(N33:Y33,1)*1), "")}
A34: =IF(ISBLANK(B34),"",A33+1) | J34: =IF(AND(NOT(ISBLANK(K34)),NOT(ISBLANK(L34))),IF(K34>L34,"W",IF(K34<L34,"L","D")),"") | K34: {=IF(L34<>"", SUMPRODUCT(MID(N34:Y34,5,1)*1), "")} | M34: {=IF(L34<>"", SUMPRODUCT(LEFT(N34:Y34,1)*1), "")}
A35: =IF(ISBLANK(B35),"",A34+1) | J35: =IF(AND(NOT(ISBLANK(K35)),NOT(ISBLANK(L35))),IF(K35>L35,"W",IF(K35<L35,"L","D")),"") | K35: {=IF(L35<>"", SUMPRODUCT(MID(N35:Y35,5,1)*1), "")} | M35: {=IF(L35<>"", SUMPRODUCT(LEFT(N35:Y35,1)*1), "")}
A36: =IF(ISBLANK(B36),"",A35+1) | J36: =IF(AND(NOT(ISBLANK(K36)),NOT(ISBLANK(L36))),IF(K36>L36,"W",IF(K36<L36,"L","D")),"") | K36: {=IF(L36<>"", SUMPRODUCT(MID(N36:Y36,5,1)*1), "")} | M36: {=IF(L36<>"", SUMPRODUCT(LEFT(N36:Y36,1)*1), "")}
A37: =IF(ISBLANK(B37),"",A36+1) | J37: =IF(AND(NOT(ISBLANK(K37)),NOT(ISBLANK(L37))),IF(K37>L37,"W",IF(K37<L37,"L","D")),"") | K37: {=IF(L37<>"", SUMPRODUCT(MID(N37:Y37,5,1)*1), "")} | M37: {=IF(L37<>"", SUMPRODUCT(LEFT(N37:Y37,1)*1), "")}
A38: =IF(ISBLANK(B38),"",A37+1) | J38: =IF(AND(NOT(ISBLANK(K38)),NOT(ISBLANK(L38))),IF(K38>L38,"W",IF(K38<L38,"L","D")),"") | K38: {=IF(L38<>"", SUMPRODUCT(MID(N38:Y38,5,1)*1), "")} | M38: {=IF(L38<>"", SUMPRODUCT(LEFT(N38:Y38,1)*1), "")}
... A40: =IF(ISBLANK(B40),"",A39+1) | J40: =IF(AND(NOT(ISBLANK(K40)),NOT(ISBLANK(L40))),IF(K40>L40,"W",IF(K40<L40,"L","D")),"") | K40: {=IF(L40<>"", SUMPRODUCT(MID(N40:Y40,5,1)*1), "")} | M40: {=IF(L40<>"", SUMPRODUCT(LEFT(N40:Y40,1)*1), "")}
B44: Adam | C44: Antek | D44: Ben | E44: Ilay | F44: James | G44: Jesse | H44: Johan | I44: Ren | J44: Yahya | K44: Maddox | L44: Kay | M44: Noam
A45: showup | B45: 1 | C45: 1 | D45: 1 | E45: 1 | F45: 1 | G45: 1 | H45: 1 | I45: 1 | J45: 1 | K45: 0 | L45: 1 | M45: 1 | N45: =SUM(B45:M45) -> 11
...

Sheet Individual
C1: Adam | D1: Antek | E1: Ben | F1: Ilay | G1: James | H1: Jesse | I1: Johan | J1: Ren | K1: Yahya | L1: Maddox | M1: Kay | N1: Noam
A2: Show-up | B2: Count | C2: {=SUM(IF(LEFT(INDEX(MatchesDB!$K$11:$Z40, 0, MATCH(C$1, MatchesDB!$K$10:$Z$10, 0)), 1)="1", 1, 0))} -> 8 | D2: {=SUM(IF(LEFT(INDEX(MatchesDB!$K$11:$Z42, 0, MATCH(D$1, MatchesDB!$K$10:$Z$10, 0)), 1)="1", 1, 0))} -> 9 | E2: {=SUM(IF(LEFT(INDEX(MatchesDB!$K$11:$Z40, 0, MATCH(E$1, MatchesDB!$K$10:$Z$10, 0)), 1)="1", 1, 0))} -> 9 | F2: {=SUM(IF(LEFT(INDEX(MatchesDB!$K$11:$Z40, 0, MATCH(F$1, MatchesDB!$K$10:$Z$10, 0)), 1)="1", 1, 0))} -> 8 | G2: {=SUM(IF(LEFT(INDEX(MatchesDB!$K$11:$Z40, 0, MATCH(G$1, MatchesDB!$K$10:$Z$10, 0)), 1)="1", 1, 0))} -> 8 | H2: {=SUM(IF(LEFT(INDEX(MatchesDB!$K$11:$Z40, 0, MATCH(H$1, MatchesDB!$K$10:$Z$10, 0)), 1)="1", 1, 0))} -> 9 | I2: {=SUM(IF(LEFT(INDEX(MatchesDB!$K$11:$Z40, 0, MATCH(I$1, MatchesDB!$K$10:$Z$10, 0)), 1)="1", 1, 0))} -> 5 | J2: {=SUM(IF(LEFT(INDEX(MatchesDB!$K$11:$Z40, 0, MATCH(J$1, MatchesDB!$K$10:$Z$10, 0)), 1)="1", 1, 0))} -> 9 | K2: {=SUM(IF(LEFT(INDEX(MatchesDB!$K$11:$Z40, 0, MATCH(K$1, MatchesDB!$K$10:$Z$10, 0)), 1)="1", 1, 0))} -> 9 | L2: {=SUM(IF(LEFT(INDEX(MatchesDB!$K$11:$Z40, 0, MATCH(L$1, MatchesDB!$K$10:$Z$10, 0)), 1)="1", 1, 0))} -> 1 | ... N2: {=SUM(IF(LEFT(INDEX(MatchesDB!$K$11:$Z40, 0, MATCH(N$1, MatchesDB!$K$10:$Z$10, 0)), 1)="1", 1, 0))} -> 4
B3: % | C3: =C2/MatchesDB!$B$1 -> 0.88888889 | D3: =D2/MatchesDB!$B$1 -> 1 | E3: =E2/MatchesDB!$B$1 -> 1 | F3: =F2/MatchesDB!$B$1 -> 0.88888889 | G3: =G2/MatchesDB!$B$1 -> 0.88888889 | H3: =H2/MatchesDB!$B$1 -> 1 | I3: =I2/MatchesDB!$B$1 -> 0.55555556 | J3: =J2/(MatchesDB!$B$1) -> 1 | K3: =K2/MatchesDB!$B$1 -> 1 | L3: =L2/MatchesDB!$B$1 -> 0.11111111 | M3: =M2/MatchesDB!$B$1 -> 0.44444444 | N3: =N2/MatchesDB!$B$1 -> 0.44444444
A4: 1st lineup | B4: Count | C4: {=SUM(IF(MID(INDEX(MatchesDB!$K$11:$Z40, 0, MATCH(C$1, MatchesDB!$K$10:$Z$10, 0)), 3, 1)="1", 1, 0))} -> 8 | D4: {=SUM(IF(MID(INDEX(MatchesDB!$K$11:$Z40, 0, MATCH(D$1, MatchesDB!$K$10:$Z$10, 0)), 3, 1)="1", 1, 0))} -> 9 | E4: {=SUM(IF(MID(INDEX(MatchesDB!$K$11:$Z40, 0, MATCH(E$1, MatchesDB!$K$10:$Z$10, 0)), 3, 1)="1", 1, 0))} -> 9 | F4: {=SUM(IF(MID(INDEX(MatchesDB!$K$11:$Z40, 0, MATCH(F$1, MatchesDB!$K$10:$Z$10, 0)), 3, 1)="1", 1, 0))} -> 7 | G4: {=SUM(IF(MID(INDEX(MatchesDB!$K$11:$Z40, 0, MATCH(G$1, MatchesDB!$K$10:$Z$10, 0)), 3, 1)="1", 1, 0))} -> 8 | H4: {=SUM(IF(MID(INDEX(MatchesDB!$K$11:$Z40, 0, MATCH(H$1, MatchesDB!$K$10:$Z$10, 0)), 3, 1)="1", 1, 0))} -> 8 | I4: {=SUM(IF(MID(INDEX(MatchesDB!$K$11:$Z40, 0, MATCH(I$1, MatchesDB!$K$10:$Z$10, 0)), 3, 1)="1", 1, 0))} -> 3 | J4: {=SUM(IF(MID(INDEX(MatchesDB!$K$11:$Z40, 0, MATCH(J$1, MatchesDB!$K$10:$Z$10, 0)), 3, 1)="1", 1, 0))} -> 9 | ... N4: {=SUM(IF(MID(INDEX(MatchesDB!$K$11:$Z40, 0, MATCH(N$1, MatchesDB!$K$10:$Z$10, 0)), 3, 1)="1", 1, 0))} -> 1
B5: % | C5: =C4/C2 -> 1 | D5: =D4/D2 -> 1 | E5: =E4/E2 -> 1 | F5: =F4/F2 -> 0.875 | G5: =G4/G2 -> 1 | H5: =H4/H2 -> 0.88888889 | I5: =I4/I2 -> 0.6 | J5: =J4/J2 -> 1 | ... N5: =N4/N2 -> 0.25
A6: Scorers | B6: Count | C6: {=SUM(IFERROR(VALUE(MID(INDEX(MatchesDB!$K$11:$Z40, 0, MATCH(C$1, MatchesDB!$K$10:$Z$10, 0)), 5, 1)), 0))} -> 0 | D6: {=SUM(IFERROR(VALUE(MID(INDEX(MatchesDB!$K$11:$Z40, 0, MATCH(D$1, MatchesDB!$K$10:$Z$10, 0)), 5, 1)), 0))} -> 9 | E6: {=SUM(IFERROR(VALUE(MID(INDEX(MatchesDB!$K$11:$Z40, 0, MATCH(E$1, MatchesDB!$K$10:$Z$10, 0)), 5, 1)), 0))} -> 4 | F6: {=SUM(IFERROR(VALUE(MID(INDEX(MatchesDB!$K$11:$Z40, 0, MATCH(F$1, MatchesDB!$K$10:$Z$10, 0)), 5, 1)), 0))} -> 3 | G6: {=SUM(IFERROR(VALUE(MID(INDEX(MatchesDB!$K$11:$Z40, 0, MATCH(G$1, MatchesDB!$K$10:$Z$10, 0)), 5, 1)), 0))} -> 2 | H6: {=SUM(IFERROR(VALUE(MID(INDEX(MatchesDB!$K$11:$Z40, 0, MATCH(H$1, MatchesDB!$K$10:$Z$10, 0)), 5, 1)), 0))} -> 0 | I6: {=SUM(IFERROR(VALUE(MID(INDEX(MatchesDB!$K$11:$Z40, 0, MATCH(I$1, MatchesDB!$K$10:$Z$10, 0)), 5, 1)), 0))} -> 2 | J6: {=SUM(IFERROR(VALUE(MID(INDEX(MatchesDB!$K$11:$Z40, 0, MATCH(J$1, MatchesDB!$K$10:$Z$10, 0)), 5, 1)), 0))} -> 7 | ... N6: {=SUM(IFERROR(VALUE(MID(INDEX(MatchesDB!$K$11:$Z40, 0, MATCH(N$1, MatchesDB!$K$10:$Z$10, 0)), 5, 1)), 0))} -> 2
B7: Average | C7: =C6/C2 -> 0 | D7: =D6/D2 -> 1 | E7: =E6/E2 -> 0.44444444 | F7: =F6/F2 -> 0.375 | G7: =G6/G2 -> 0.25 | H7: =H6/H2 -> 0 | I7: =I6/I2 -> 0.4 | J7: =J6/J2 -> 0.77777778 | ... N7: =N6/N2 -> 0.5
A8: Assists | B8: Count | C8: {=SUM(IFERROR(VALUE(MID(INDEX(MatchesDB!$K$11:$Z40, 0, MATCH(C$1, MatchesDB!$K$10:$Z$10, 0)), 7, 1)), 0))} -> 0 | D8: {=SUM(IFERROR(VALUE(MID(INDEX(MatchesDB!$K$11:$Z40, 0, MATCH(D$1, MatchesDB!$K$10:$Z$10, 0)), 7, 1)), 0))} -> 3 | E8: {=SUM(IFERROR(VALUE(MID(INDEX(MatchesDB!$K$11:$Z40, 0, MATCH(E$1, MatchesDB!$K$10:$Z$10, 0)), 7, 1)), 0))} -> 5 | F8: {=SUM(IFERROR(VALUE(MID(INDEX(MatchesDB!$K$11:$Z40, 0, MATCH(F$1, MatchesDB!$K$10:$Z$10, 0)), 7, 1)), 0))} -> 2 | G8: {=SUM(IFERROR(VALUE(MID(INDEX(MatchesDB!$K$11:$Z40, 0, MATCH(G$1, MatchesDB!$K$10:$Z$10, 0)), 7, 1)), 0))} -> 0 | H8: {=SUM(IFERROR(VALUE(MID(INDEX(MatchesDB!$K$11:$Z40, 0, MATCH(H$1, MatchesDB!$K$10:$Z$10, 0)), 7, 1)), 0))} -> 1 | I8: {=SUM(IFERROR(VALUE(MID(INDEX(MatchesDB!$K$11:$Z40, 0, MATCH(I$1, MatchesDB!$K$10:$Z$10, 0)), 7, 1)), 0))} -> 0 | J8: {=SUM(IFERROR(VALUE(MID(INDEX(MatchesDB!$K$11:$Z40, 0, MATCH(J$1, MatchesDB!$K$10:$Z$10, 0)), 7, 1)), 0))} -> 5 | ... N8: {=SUM(IFERROR(VALUE(MID(INDEX(MatchesDB!$K$11:$Z40, 0, MATCH(N$1, MatchesDB!$K$10:$Z$10, 0)), 7, 1)), 0))} -> 0
B9: Average | C9: =C8/C2 -> 0 | D9: =D8/D2 -> 0.33333333 | E9: =E8/E2 -> 0.55555556 | F9: =F8/F2 -> 0.25 | G9: =G8/G2 -> 0 | H9: =H8/H2 -> 0.11111111 | I9: =I8/I2 -> 0 | J9: =J8/J2 -> 0.55555556 | ... N9: =N8/N2 -> 0
A10: Goal contribution | B10: Count | C10: =C6+C8 -> 0 | D10: =D6+D8 -> 12 | E10: =E6+E8 -> 9 | F10: =F6+F8 -> 5 | G10: =G6+G8 -> 2 | H10: =H6+H8 -> 1 | I10: =I6+I8 -> 2 | J10: =J6+J8 -> 12 | ... N10: =N6+N8 -> 2
B11: Average | C11: =C10/C2 -> 0 | D11: =D10/D2 -> 1.3333333 | E11: =E10/E2 -> 1 | F11: =F10/F2 -> 0.625 | G11: =G10/G2 -> 0.25 | H11: =H10/H2 -> 0.11111111 | I11: =I10/I2 -> 0.4 | J11: =J10/J2 -> 1.3333333 | ... N11: =N10/N2 -> 0.5
